# -*- coding: utf-8 -*-
"""visualization-covid19-georgia.ipynb

Automatically generated by Colaboratory.

Original file is located at
    https://colab.research.google.com/drive/1KhkSM3sddPATo-IXiECKScN2WEIVJru_
"""



"""# Step 1: Loading in packages"""

# the below packages are related to loading and performing basic
# transformations of the data

import pandas as pd
import numpy as np

print('cell sucessfully ran')

# now we are going to load in some visualization packages to help create
# visuals of the data

import seaborn as sns
import matplotlib.pyplot as plt
import plotly.express as plt

sns.set_theme(style="whitegrid")
print('cell sucessfully ran')

"""# Loading in Data"""

dataframe = pd.read_csv('https://raw.githubusercontent.com/bsthomas96/AHI_Microcourse_Visualization/main/Data/Georgia_COVID/Georgia_COVID-19_Case_Data.csv')

dataframe

len(dataframe)

dataframe.shape

"""# Describing the variables"""

dataframe.info()

list(dataframe)

dataframe['COUNTY'].value_counts()

dataframe_counties = dataframe['COUNTY'].value_counts()
dataframe_counties.head(20)

"""## Transforming Columns"""

dataframe['DATESTAMP']

# creating a copy of the existing column, so we keep the original version
# we could also override the column if we wanted to, but because we are unsure 
# where we are going to take the analysis - lets just keep it

dataframe['DATESTAMP_MOD'] = dataframe['DATESTAMP']
print(dataframe['DATESTAMP_MOD'].head(10))
print(dataframe['DATESTAMP_MOD'].dtypes)

dataframe['DATESTAMP_MOD'] = pd.to_datatime(dataframe['DATESTAMP_MOD'])
dataframe['DATESTAMP_MOD'].dtypes

# error above when trying to get datetime

dataframe[['DATESTAMP', 'DATESTAMP_MOD']]

dataframe['DATESTAMP_MOD_DAY'] = dataframe['DATESTAMP_MOD'].dt.date
dataframe['DATESTAMP_MOD_DAY']

# error due to datetime error before 
# was unable to solve this error

dataframe['DATESTAMP_MOD_YEAR'] = dataframe['DATESTAMP_MOD'].dt.year
dataframe['DATESTAMP_MOD_MONTH'] = dataframe['DATASTAMP_MOD'].dt.month

# error continued

dataframe['DATESTAMP_MOD_YEAR']

# error due to datetime issue continued

dataframe['DATESTANP_MOD_MONTH']